Workbook

Sheet Mann 05 25_historical
A1: Family | B1: Region | C1: Salesman | D1: Client | E1: Category | F1: Subcategory | G1: SKU | H1: Description | I1: Periods Per Year | J1: 42736 | K1: 42767 | L1: 42795 | M1: 42826 | N1: 42856 | O1: 42887 | P1: 42917 | Q1: 42948 | R1: 42979 | S1: 43009 | T1: 43040 | U1: 43070 | V1: 43101 | W1: 43132 | X1: 43160 | Y1: 43191 | Z1: 43221 | AA1: 43252 | AB1: 43282 | AC1: 43313 | AD1: 43344 | AE1: 43374 | AF1: 43405 | AG1: 43435 | AH1: 43466 | AI1: 43497 | AJ1: 43525 | AK1: 43556 | AL1: 43586 | AM1: 43617 | AN1: 43647 | AO1: 43678 | AP1: 43709 | AQ1: 43739 | AR1: 43770 | AS1: 43800 | AT1: 43831 | AU1: 43862 | AV1: 43891 | AW1: 43922 | AX1: 43952 | AY1: 43983 | AZ1: 44013 | BA1: 44044 | BB1: 44075 | BC1: 44105 | BD1: 44136 | BE1: 44166 | BF1: 44197 | BG1: 44228 | BH1: 44256 | BI1: 44287 | BJ1: 44317 | BK1: 44348 | BL1: 44378 | BM1: 44409 | BN1: 44440 | BO1: 44470 | BP1: 44501 | BQ1: 44531 | BR1: 44562 | BS1: 44593 | BT1: 44621 | BU1: 44652 | BV1: 44682 | BW1: 44713 | BX1: 44743 | BY1: 44774 | BZ1: 44805 | CA1: 44835 | CB1: 44866 | CC1: 44896 | CD1: 44927 | CE1: 44958 | CF1: 44986 | CG1: 45017 | CH1: 45047 | CI1: 45078 | CJ1: 45108 | CK1: 45139 | CL1: 45170 | CM1: 45200 | CN1: 45231 | CO1: 45261 | CP1: 45292 | CQ1: 45323 | CR1: 45352 | CS1: 45383 | CT1: 45413 | CU1: 45444 | CV1: 45474 | CW1: 45505 | CX1: 45536 | CY1: 45566 | CZ1: 45597 | DA1: 45627 | DB1: 45658 | DC1: 45689 | DD1: 45717 | DE1: 45748 | DF1: 45778 | DG1: 45809 | DH1: 45839
B2: VSF | D2: MANN-FILTER | E2: PC | F2: Air Filter | G2: C 16 012 | H2: CHEVROLET Cruze 1.4 T 86CID 153CV (Reemplaza a C 14 013) | I2: 12 | BD2: 34 | BE2: 122 | BF2: 284 | BG2: 170 | BH2: 170 | BI2: 146 | BJ2: 190 | BK2: 316 | BL2: 114 | BM2: 94 | BP2: 181 | BQ2: 693 | BR2: 571 | BT2: 180 | BU2: 861 | BV2: 105 | BW2: 635 | BX2: 362 | BY2: 336 | BZ2: 156 | CA2: 500 | CB2: 282 | CC2: 104 | CD2: 348 | CE2: 164 | CF2: 439 | CG2: 545 | CH2: 240 | CI2: 96 | CJ2: 996 | CM2: 1358 | CN2: 508 | CO2: 363 | CP2: 1423 | CQ2: 195 | CR2: 152 | CS2: 666 | CT2: 614 | CU2: 386 | CV2: 544 | CW2: 513 | CX2: 540 | CY2: 666 | CZ2: 24 | DA2: 878 | DB2: 552 | DC2: 1090 | DD2: 360 | DE2: 892 | DF2: 186 | DG2: =IFERROR(VLOOKUP(G2,Hoja2!$C$1:$E$1548,3,FALSE),0) -> 542 | DH2: =IFERROR(VLOOKUP(G2,Hoja2!$O$1:$P$1906,2,FALSE),0) -> 726
B3: VSF | D3: MANN-FILTER | E3: PC | F3: Air Filter | G3: C 16 134/2 | H3: Ford Focus 2.0L motor Duratec HE; 1.6L 16V motor Sigma 2008 Ã¢â€ â€™; 1.8 TDCi motor KKDA 2008 Ã¢â€ â€™ (Reemplaza a C 16 134/1) | I3: 12 | BB3: 333 | BC3: 510 | BD3: 180 | BE3: 464 | BF3: 100 | BG3: 1200 | BH3: 680 | BI3: 528 | BJ3: 644 | BK3: 200 | BL3: 320 | BM3: 580 | BN3: 450 | BP3: 510 | BQ3: 686 | BR3: 848 | BS3: 2141 | BT3: 101 | BU3: 1660 | BV3: 1835 | BW3: 1342 | BX3: 703 | BY3: 390 | BZ3: 410 | CA3: 910 | CB3: 530 | CC3: 480 | CD3: 620 | CE3: 1036 | CF3: 1100 | CG3: 1240 | CH3: 216 | CI3: 610 | CJ3: 956 | CK3: 20 | CL3: 1004 | CM3: 990 | CN3: 1156 | CO3: 444 | CP3: 600 | CQ3: 422 | CR3: 740 | CS3: 320 | CT3: 340 | CU3: 800 | CV3: 1340 | CW3: 743 | CX3: 761 | CY3: 338 | CZ3: 482 | DA3: 600 | DB3: 720 | DC3: 574 | DD3: 700 | DF3: 1953 | DG3: =IFERROR(VLOOKUP(G3,Hoja2!$C$1:$E$1548,3,FALSE),0) -> 147 | DH3: =IFERROR(VLOOKUP(G3,Hoja2!$O$1:$P$1906,2,FALSE),0) -> 2158
B4: VSF | D4: MANN-FILTER | E4: PC | F4: Air Filter | G4: C 18 004 | H4: HONDA CITY 1.5 16V SOHC i-VTEC 07/09 - FIT 1.4 16v 01/09 | I4: 12 | J4: 164 | K4: 156 | L4: 300 | M4: 54 | O4: 610 | P4: 206 | Q4: 100 | R4: 200 | S4: 362 | T4: 44 | U4: 196 | V4: 140 | W4: 374 | X4: 243 | Y4: 247 | Z4: 176 | AA4: 306 | AB4: 153 | AC4: 152 | AD4: 643 | AF4: 105 | AG4: 150 | AH4: 1157 | AI4: 114 | AJ4: 146 | AK4: 203 | AL4: 106 | AM4: 60 | AN4: 218 | AO4: 144 | AP4: 234 | AQ4: 208 | AR4: 80 | AS4: 200 | AT4: 219 | AU4: 406 | AV4: 1 | AW4: 200 | AX4: 245 | AY4: 301 | AZ4: 255 | BA4: 204 | BB4: 100 | BC4: 60 | BD4: 410 | BE4: 5 | BF4: 141 | BG4: 290 | BH4: 90 | BI4: 102 | BJ4: 210 | BK4: 340 | BL4: 172 | BM4: 55 | BN4: 205 | BP4: 86 | BQ4: 334 | BR4: 190 | BS4: 80 | BT4: 480 | BU4: 440 | BV4: 385 | BW4: 250 | BX4: 10 | BY4: 194 | BZ4: 120 | CA4: 150 | CB4: 160 | CC4: 80 | CD4: 420 | CE4: 80 | CF4: 510 | CG4: 220 | CH4: 120 | CI4: 460 | CJ4: 650 | CK4: 60 | CL4: 10 | CM4: 270 | CO4: 300 | CP4: 450 | CQ4: 210 | CR4: 170 | CS4: 210 | CT4: 240 | CU4: 160 | CV4: 260 | CW4: 330 | CX4: 190 | CY4: 120 | CZ4: 310 | DA4: 140 | DB4: 204 | DC4: 110 | DD4: 450 | DE4: 156 | DF4: 300 | DG4: =IFERROR(VLOOKUP(G4,Hoja2!$C$1:$E$1548,3,FALSE),0) -> 500 | DH4: =IFERROR(VLOOKUP(G4,Hoja2!$O$1:$P$1906,2,FALSE),0) -> 1020
B5: VSF | D5: MANN-FILTER | E5: PC | F5: Air Filter | G5: C 2324 | H5: GM AVEO 1,6 L 16V DOHC 2009Ã¢â€ â€™ SUZUKI S | I5: 12 | J5: 252 | K5: 792 | L5: 474 | M5: 260 | N5: 325 | O5: 202 | P5: 154 | Q5: 342 | R5: 336 | S5: 408 | T5: 450 | U5: 178 | V5: 480 | W5: 174 | X5: 395 | Y5: 545 | Z5: 500 | AA5: 228 | AB5: 180 | AC5: 228 | AD5: 222 | AE5: 120 | AF5: 94 | AG5: 58 | AH5: 982 | AI5: 252 | AJ5: 354 | AK5: 234 | AL5: 132 | AM5: 120 | AN5: 96 | AO5: 100 | AP5: 120 | AQ5: 201 | AR5: 230 | AS5: 166 | AT5: 116 | AU5: 111 | AV5: 5 | AW5: 146 | AX5: 602 | AY5: 291 | AZ5: 84 | BA5: 130 | BB5: 80 | BC5: 120 | BD5: 80 | BE5: 90 | BF5: 100 | BG5: 185 | BH5: 405 | BI5: 40 | BJ5: 140 | BK5: 250 | BL5: 150 | BM5: 80 | BN5: 96 | BQ5: 354 | BR5: 280 | BS5: 10 | BT5: 221 | BU5: 49 | BV5: 56 | BW5: 324 | BX5: 146 | BY5: 215 | BZ5: 59 | CA5: 300 | CB5: 220 | CC5: 90 | CD5: 150 | CE5: 230 | CF5: 220 | CG5: 181 | CH5: 199 | CI5: 160 | CJ5: 60 | CK5: 170 | CM5: 220 | CN5: 410 | CO5: 30 | CP5: 120 | CQ5: 70 | CR5: 190 | CS5: 80 | CT5: 110 | CU5: 40 | CV5: 110 | CW5: 80 | CX5: 70 | CY5: 130 | CZ5: 70 | DA5: 60 | DB5: 40 | DC5: 140 | DD5: 140 | DE5: 160 | DF5: 80 | DG5: =IFERROR(VLOOKUP(G5,Hoja2!$C$1:$E$1548,3,FALSE),0) -> 140 | DH5: =IFERROR(VLOOKUP(G5,Hoja2!$O$1:$P$1906,2,FALSE),0) -> 10
B6: VSF | D6: MANN-FILTER | E6: PC | F6: Air Filter | G6: C 24 005 | H6: TOYOTA COROLLA, 1,8 L 16V 2009Ã¢â€ â€™ | I6: 12 | J6: 260 | K6: 315 | L6: 332 | M6: 102 | N6: 205 | O6: 559 | P6: 242 | Q6: 289 | R6: -23 | S6: -5 | Y6: 28 | Z6: -23 | AO6: 10 | AP6: 200 | AQ6: 70 | AR6: 100 | AT6: 94 | AU6: 85 | AV6: 90 | AW6: 22 | AY6: 296 | BA6: 126 | BB6: 140 | BC6: 100 | BD6: 78 | BE6: 64 | BF6: 94 | BG6: 136 | BH6: 88 | BI6: 34 | BJ6: 268 | BL6: 200 | BM6: 106 | BN6: 5 | BP6: 120 | BQ6: 204 | BR6: 131 | BS6: 89 | BT6: 75 | BU6: 60 | BV6: 138 | BW6: 620 | BX6: 257 | BY6: 90 | BZ6: 469 | CA6: 248 | CB6: 6 | CC6: 677 | CD6: 450 | CE6: 485 | CF6: 375 | CG6: 1209 | CH6: 506 | CI6: 250 | CJ6: 83 | CM6: 1161 | CN6: 631 | CP6: 1222 | CQ6: 81 | CR6: 111 | CS6: 1339 | CT6: 400 | CU6: 505 | CV6: 518 | CW6: 475 | CX6: 650 | CY6: 622 | CZ6: 348 | DA6: 47 | DB6: 9 | DC6: 1000 | DD6: 600 | DE6: 998 | DF6: 400 | DG6: =IFERROR(VLOOKUP(G6,Hoja2!$C$1:$E$1548,3,FALSE),0) -> 1000 | DH6: =IFERROR(VLOOKUP(G6,Hoja2!$O$1:$P$1906,2,FALSE),0) -> 1006
B7: VSF | D7: MANN-FILTER | E7: PC | F7: Air Filter | G7: C 27 009 | H7: AUDI A3 TFSI 1.4 122 CV y VW TFSI 1.4 Golf 2014Ã¢â€ â€™ | I7: 12 | J7: 35 | K7: 45 | L7: 94 | N7: 81 | O7: 35 | P7: 65 | Q7: 70 | R7: 9 | S7: 48 | T7: 97 | U7: 98 | V7: 60 | W7: 104 | X7: 49 | Y7: 57 | Z7: 40 | AA7: 85 | AB7: 184 | AC7: 100 | AD7: 66 | AF7: 120 | AG7: 181 | AH7: 322 | AI7: 116 | AJ7: 285 | AK7: 55 | AL7: 813 | AM7: 140 | AN7: 150 | AO7: 71 | AP7: 195 | AQ7: 107 | AR7: 210 | AS7: 175 | AT7: 194 | AU7: 35 | AX7: 215 | AY7: 353 | AZ7: 225 | BA7: 210 | BB7: 282 | BC7: 70 | BD7: 80 | BE7: 282 | BF7: 245 | BG7: 215 | BH7: 82 | BI7: 216 | BJ7: 280 | BK7: 185 | BL7: 80 | BM7: 260 | BN7: 80 | BP7: 80 | BQ7: 550 | BR7: 135 | BS7: 265 | BT7: 984 | BU7: 514 | BV7: 6 | BW7: 30 | BX7: 327 | BY7: 436 | BZ7: 250 | CA7: 505 | CB7: 228 | CC7: 420 | CD7: 310 | CE7: 140 | CF7: 160 | CG7: 699 | CH7: 363 | CI7: 332 | CJ7: 294 | CM7: 635 | CN7: 115 | CO7: 350 | CP7: 712 | CQ7: 378 | CR7: 140 | CS7: 665 | CT7: 382 | CU7: 485 | CV7: 330 | CW7: 195 | CX7: 440 | CY7: 335 | CZ7: 355 | DA7: 366 | DB7: 720 | DC7: 379 | DD7: 660 | DE7: 415 | DF7: 254 | DG7: =IFERROR(VLOOKUP(G7,Hoja2!$C$1:$E$1548,3,FALSE),0) -> 451 | DH7: =IFERROR(VLOOKUP(G7,Hoja2!$O$1:$P$1906,2,FALSE),0) -> 720
B8: VSF | D8: MANN-FILTER | E8: PC | F8: Air Filter | G8: C 27 063 | H8: TOYOTA Corolla 2.0 170 cv, 2020Ã¢â€ â€™; Camry, RAV4 2.5 Hib. 218 cv, 2019Ã¢â€ â€™ | I8: 12 | CA8: 205 | CB8: 95 | CC8: 205 | CD8: 160 | CE8: 40 | CF8: 120 | CG8: 235 | CH8: 50 | CI8: 135 | CM8: 595 | CN8: 315 | CO8: 30 | CP8: 140 | CQ8: 150 | CR8: 80 | CS8: 75 | CT8: 125 | CU8: 130 | CV8: 185 | CW8: 110 | CX8: 155 | CY8: 130 | CZ8: 150 | DA8: 160 | DB8: 245 | DC8: 155 | DF8: 245 | DG8: =IFERROR(VLOOKUP(G8,Hoja2!$C$1:$E$1548,3,FALSE),0) -> 290 | DH8: =IFERROR(VLOOKUP(G8,Hoja2!$O$1:$P$1906,2,FALSE),0) -> 375
B9: VSF | D9: MANN-FILTER | E9: PC | F9: Air Filter | G9: C 36 003 | H9: Citroen DS4 1.6 16V THP 163 cv motor: EP6CDT M; Citroen DS3 1.6 16V Turbo motor EP6DT; Peugeot RCZ 1.6 16V motor EP6CDTX; 3008 1.6 THP; 308 1.6L THP CC y 1.6 GTI; 408 1.6N THP (Sport) motor EP6CDT | I9: 12 | J9: 73 | K9: 152 | L9: 140 | M9: 84 | N9: 88 | O9: 25 | P9: 402 | Q9: 266 | R9: 335 | S9: 40 | T9: 80 | U9: 100 | V9: 165 | W9: 173 | X9: 218 | AB9: 572 | AC9: 125 | AD9: 150 | AE9: 80 | AF9: 206 | AG9: 176 | AH9: 165 | AI9: 115 | AJ9: 120 | AK9: 834 | AL9: 124 | AM9: 134 | AN9: 220 | AO9: 98 | AP9: 135 | AQ9: 359 | AR9: 242 | AS9: 320 | AT9: 220 | AU9: 292 | AV9: 86 | AW9: 83 | AX9: 30 | AY9: 165 | AZ9: 91 | BA9: 90 | BB9: 17 | BC9: 404 | BD9: 115 | BE9: 24 | BF9: 262 | BG9: 10 | BH9: 346 | BI9: 104 | BJ9: 770 | BK9: 135 | BL9: 60 | BM9: 550 | BN9: 150 | BP9: 385 | BQ9: 240 | BR9: 220 | BS9: 265 | BT9: 290 | BU9: 285 | BW9: 200 | BX9: 195 | BY9: 205 | BZ9: 315 | CA9: 800 | CB9: 15 | CC9: 145 | CD9: 185 | CE9: 350 | CF9: 200 | CG9: 665 | CH9: 75 | CI9: 440 | CJ9: 400 | CK9: 5 | CM9: 625 | CN9: 485 | CO9: 190 | CP9: 340 | CQ9: 44 | CR9: 43 | CS9: 125 | CU9: 882 | CV9: 285 | CW9: 251 | CX9: 185 | CY9: 140 | CZ9: 327 | DA9: 85 | DB9: 353 | DC9: 140 | DD9: 215 | DE9: 270 | DF9: 250 | DG9: =IFERROR(VLOOKUP(G9,Hoja2!$C$1:$E$1548,3,FALSE),0) -> 102 | DH9: =IFERROR(VLOOKUP(G9,Hoja2!$O$1:$P$1906,2,FALSE),0) -> 378
B10: VSF | D10: MANN-FILTER | E10: CV | F10: Air Filter | G10: C 811 | H10: VW Camiones Serie 19.330-19.420- 26.420 2014Ã¢â€ â€™ - FORD Camiones 1933 2016Ã¢â€ â€™ | I10: 12 | Z10: 4 | AA10: 26 | AF10: 12 | AH10: 20 | AI10: 12 | AJ10: 26 | AO10: 10 | AP10: 38 | AQ10: 24 | AS10: 10 | AT10: 10 | AU10: 32 | AW10: 4 | AX10: 14 | AZ10: 21 | BA10: 10 | BC10: 26 | BD10: 4 | BE10: 44 | BF10: 32 | BH10: 44 | BI10: -8 | BJ10: 109 | BK10: 21 | BL10: 16 | BM10: 938 | BN10: 42 | BO10: 22 | BQ10: 815 | BR10: 67 | BS10: 20 | BT10: 32 | BU10: 12 | BV10: 40 | BW10: 14 | BX10: 18 | CA10: 30 | CB10: 6 | CC10: 207 | CD10: 980 | CE10: 528 | CF10: 504 | CG10: 22 | CH10: 187 | CJ10: 1670 | CK10: 264 | CL10: 12 | CM10: 652 | CN10: 64 | CO10: 1076 | CP10: 1016 | CQ10: 2400 | CR10: 34 | CS10: 524 | CT10: 24 | CU10: 18 | CV10: 25 | CW10: 12 | CX10: 432 | CY10: 431 | CZ10: 4 | DA10: 8 | DB10: 806 | DC10: 100 | DD10: 5 | DE10: 1308 | DF10: 930 | DG10: =IFERROR(VLOOKUP(G10,Hoja2!$C$1:$E$1548,3,FALSE),0) -> 0 | DH10: =IFERROR(VLOOKUP(G10,Hoja2!$O$1:$P$1906,2,FALSE),0) -> 1630
B11: VSF | D11: MANN-FILTER | E11: CV | F11: Air Filter | G11: CF 1650 | H11: cart. De seg. Para C 26 1100 | I11: 12 | J11: 118 | K11: 120 | N11: 189 | O11: 379 | P11: 257 | Q11: 21 | R11: -95 | S11: 25 | T11: 132 | U11: 169 | V11: 217 | W11: 70 | X11: 37 | Y11: 268 | Z11: 42 | AA11: 8 | AB11: 67 | AC11: 161 | AD11: 30 | AF11: 85 | AG11: 18 | AH11: 240 | AI11: 157 | AJ11: 27 | AK11: 265 | AL11: 30 | AM11: 58 | AN11: 55 | AO11: 125 | AP11: 56 | AQ11: 147 | AR11: 16 | AS11: 275 | AT11: 146 | AU11: 360 | AV11: 45 | AW11: -8 | AX11: 30 | AY11: 140 | AZ11: 62 | BC11: 6 | BE11: 20 | BF11: 62 | BG11: 5 | BH11: 69 | BJ11: 64 | BK11: 118 | BL11: 152 | BM11: 10 | BN11: 222 | BO11: 90 | BP11: 16 | BR11: 143 | BS11: 26 | BT11: 23 | BV11: 811 | BW11: 702 | BX11: 91 | BY11: 22 | BZ11: 24 | CA11: 245 | CB11: 76 | CC11: 22 | CD11: 234 | CE11: 258 | CF11: 541 | CG11: 180 | CH11: 2 | CI11: 362 | CJ11: 408 | CK11: 32 | CM11: 199 | CN11: 120 | CO11: 262 | CP11: 53 | CQ11: 55 | CR11: 78 | CS11: 18 | CT11: 214 | CU11: 247 | CV11: 55 | CW11: 328 | CX11: 61 | CY11: 193 | CZ11: 112 | DA11: 200 | DB11: 160 | DC11: 520 | DD11: 40 | DE11: 178 | DF11: 682 | DG11: =IFERROR(VLOOKUP(G11,Hoja2!$C$1:$E$1548,3,FALSE),0) -> 340 | DH11: =IFERROR(VLOOKUP(G11,Hoja2!$O$1:$P$1906,2,FALSE),0) -> 284
B12: VSF | D12: MANN-FILTER | E12: OHI | F12: Air Filter | G12: CF 810 | H12: (Cart. Segur. para C 30 810/3) | I12: 12 | J12: 40 | K12: 15 | L12: 10 | M12: 43 | N12: 20 | O12: 25 | P12: 23 | Q12: 57 | R12: 2 | S12: 57 | T12: 19 | U12: 120 | W12: 141 | X12: 5 | Y12: 34 | Z12: 120 | AA12: 70 | AB12: 60 | AC12: 54 | AD12: 62 | AE12: 61 | AF12: 60 | AG12: 66 | AI12: 61 | AJ12: 61 | AK12: 60 | AL12: 66 | AN12: 114 | AO12: 50 | AP12: 62 | AQ12: 50 | AR12: 60 | AS12: 53 | AT12: 52 | AU12: 56 | AV12: 50 | AW12: 2 | AX12: 52 | AY12: 50 | BB12: 10 | BC12: 120 | BE12: 47 | BF12: 157 | BG12: 4 | BI12: 254 | BJ12: 100 | BK12: 6 | BL12: 72 | BM12: 458 | BN12: 380 | BP12: 4 | BR12: 612 | BS12: 4 | BT12: 200 | BU12: 226 | BV12: 8 | BW12: 6 | BX12: 2 | BY12: 26 | BZ12: 154 | CA12: 152 | CB12: 152 | CC12: 150 | CD12: 6 | CE12: 24 | CF12: 4 | CG12: 150 | CH12: 4 | CJ12: 106 | CK12: 124 | CM12: 2 | CR12: 4 | CS12: 56 | CV12: 13 | CZ12: 4 | DC12: 6 | DF12: 2 | DG12: =IFERROR(VLOOKUP(G12,Hoja2!$C$1:$E$1548,3,FALSE),0) -> 50 | DH12: =IFERROR(VLOOKUP(G12,Hoja2!$O$1:$P$1906,2,FALSE),0) -> 54
B13: VSF | D13: MANN-FILTER | E13: Pick up | F13: Cabin Filter | G13: CU 1919 | H13: TOYOTA: Corolla/Fielder 1.8 16V Flex 2009Ã¢â€ â€™; Hilux 2.5/3.0 L 16V Diesel 2001Ã¢â€ â€™; Hilux 2.5/3.0 L 16V Diesel 2005Ã¢â€ â€™; RAV4 2.0 16V Gas. 2006Ã¢â€ â€™; Camry 2006Ã¢â€ â€™; Lexus 2006Ã¢â€ â€™ | I13: 12 | J13: 989 | K13: 795 | L13: 180 | N13: 309 | O13: 2055 | Q13: 870 | R13: 1282 | S13: 70 | T13: 658 | U13: 691 | V13: 769 | W13: 727 | X13: 1011 | Y13: 456 | Z13: 520 | AA13: 581 | AB13: 624 | AC13: 304 | AD13: 1396 | AF13: 1603 | AG13: 65 | AH13: 1455 | AI13: 814 | AJ13: 816 | AK13: 436 | AL13: 400 | AM13: 345 | AN13: 404 | AO13: 90 | AP13: 754 | AQ13: 527 | AR13: 931 | AS13: 1336 | AT13: 1895 | AU13: 10 | AV13: 195 | AW13: 410 | AX13: 712 | AY13: 450 | AZ13: 710 | BA13: 320 | BB13: 360 | BC13: 930 | BD13: 260 | BE13: 300 | BF13: 712 | BG13: 1270 | BH13: 512 | BI13: 1350 | BJ13: 112 | BK13: 720 | BL13: 530 | BM13: 1840 | BN13: 2900 | BP13: 350 | BQ13: 490 | BR13: 1031 | BS13: 1419 | BT13: 450 | BU13: 2415 | BV13: 2260 | BW13: 1210 | BX13: 490 | BY13: 1018 | BZ13: 912 | CA13: 570 | CB13: 640 | CC13: 2390 | CD13: 1540 | CE13: 2649 | CF13: 2058 | CG13: 640 | CH13: 1983 | CI13: 145 | CJ13: 961 | CM13: 2832 | CN13: 1548 | CO13: 813 | CP13: 1529 | CQ13: 126 | CR13: 105 | CS13: 2485 | CT13: 265 | CU13: 470 | CV13: 1180 | CX13: 1975 | CZ13: 2870 | DA13: 1560 | DB13: 3830 | DC13: 921 | DD13: 1869 | DE13: 390 | DF13: 1170 | DG13: =IFERROR(VLOOKUP(G13,Hoja2!$C$1:$E$1548,3,FALSE),0) -> 2231 | DH13: =IFERROR(VLOOKUP(G13,Hoja2!$O$1:$P$1906,2,FALSE),0) -> 670
B14: VSF | D14: MANN-FILTER | E14: PC | F14: Cabin Filter | G14: CU 21 000-2 | H14: CitroÃƒÂ«n Peugeot 1,6 16 V Turbo | I14: 12 | J14: 159 | K14: 123 | L14: 86 | P14: 182 | Q14: 112 | R14: 38 | S14: 49 | T14: 96 | U14: 329 | V14: 43 | W14: 146 | X14: 235 | Y14: 121 | Z14: 74 | AA14: 26 | AB14: 75 | AC14: 35 | AD14: 132 | AE14: 87 | AF14: 87 | AG14: 98 | AH14: 467 | AI14: 180 | AJ14: 117 | AK14: 127 | AL14: 155 | AM14: 186 | AN14: 156 | AO14: 28 | AP14: 121 | AQ14: 203 | AR14: 169 | AS14: 260 | AT14: 255 | AU14: 139 | AW14: 47 | AX14: 362 | AY14: 78 | AZ14: 226 | BA14: 114 | BB14: 272 | BC14: 168 | BD14: 200 | BE14: 134 | BF14: 58 | BG14: 222 | BH14: 192 | BI14: 148 | BJ14: 602 | BK14: 299 | BL14: 285 | BM14: 258 | BN14: 326 | BP14: 146 | BQ14: 212 | BR14: 614 | BS14: 24 | BT14: 432 | BU14: 454 | BV14: 188 | BW14: 59 | BX14: 388 | BY14: 413 | BZ14: 1037 | CA14: 872 | CB14: 250 | CC14: 1000 | CD14: 696 | CE14: 738 | CF14: 90 | CG14: 1126 | CH14: 676 | CI14: 462 | CJ14: 618 | CK14: 131 | CM14: 589 | CN14: 546 | CO14: 704 | CP14: 72 | CQ14: 266 | CR14: 1084 | CS14: 344 | CT14: 100 | CU14: 82 | CV14: 438 | CW14: 216 | CX14: 198 | CY14: 376 | CZ14: 432 | DA14: 450 | DB14: 326 | DC14: 538 | DE14: 714 | DF14: 4 | DG14: =IFERROR(VLOOKUP(G14,Hoja2!$C$1:$E$1548,3,FALSE),0) -> 838 | DH14: =IFERROR(VLOOKUP(G14,Hoja2!$O$1:$P$1906,2,FALSE),0) -> 565
B15: VSF | D15: MANN-FILTER | E15: PC | F15: Cabin Filter | G15: CU 2141 | H15: CITROEN C4 aircross 2013 / Peugeot 4008 / Mitsubishi Outlander III 2.0 | I15: 12 | J15: 114 | K15: 66 | L15: 8 | M15: 5 | N15: -1 | O15: 136 | P15: 8 | Q15: 14 | R15: 130 | S15: 11 | T15: 16 | U15: 225 | V15: 37 | W15: 211 | X15: 86 | Y15: 114 | Z15: 58 | AA15: 50 | AB15: 52 | AC15: 126 | AD15: 82 | AF15: 299 | AG15: 183 | AH15: 160 | AI15: 113 | AJ15: 173 | AK15: 44 | AL15: 88 | AM15: 92 | AN15: 78 | AO15: 28 | AP15: 50 | AQ15: 202 | AR15: 114 | AS15: 170 | AT15: 140 | AU15: 306 | AV15: 52 | AW15: 36 | AX15: 47 | AY15: 120 | AZ15: 325 | BA15: 53 | BB15: 30 | BC15: 50 | BD15: 200 | BE15: 281 | BF15: 105 | BG15: 84 | BJ15: 806 | BK15: 305 | BL15: 35 | BM15: 875 | BN15: 95 | BO15: 110 | BP15: 32 | BQ15: 170 | BR15: 253 | BT15: 462 | BU15: 432 | BV15: 160 | BW15: 572 | BX15: 185 | BY15: 54 | BZ15: 480 | CA15: 480 | CB15: 110 | CC15: 375 | CD15: 255 | CE15: 488 | CF15: 235 | CG15: 205 | CH15: 227 | CI15: 365 | CM15: 349 | CN15: 555 | CO15: 205 | CP15: 65 | CQ15: 200 | CR15: 110 | CS15: 155 | CT15: 80 | CU15: 115 | CV15: 190 | CW15: 180 | CX15: 160 | CY15: 460 | CZ15: 305 | DA15: 100 | DB15: 410 | DC15: 310 | DD15: 130 | DE15: 300 | DF15: 97 | DG15: =IFERROR(VLOOKUP(G15,Hoja2!$C$1:$E$1548,3,FALSE),0) -> 300 | DH15: =IFERROR(VLOOKUP(G15,Hoja2!$O$1:$P$1906,2,FALSE),0) -> 115
B16: VSF | D16: MANN-FILTER | E16: PC | F16: Cabin Filter | G16: CU 22 019 | H16: Renault Duster-Logan-Sandero | I16: 12 | J16: 206 | K16: 276 | L16: 269 | N16: -2 | P16: 500 | Q16: 54 | R16: 33 | S16: 35 | T16: 267 | U16: 188 | V16: 241 | W16: 439 | X16: 140 | Y16: 252 | Z16: 189 | AA16: 85 | AB16: 3 | AC16: 96 | AD16: 110 | AE16: 30 | AF16: 210 | AG16: 34 | AH16: 826 | AI16: 347 | AJ16: 196 | AK16: 122 | AL16: 262 | AM16: 28 | AN16: 221 | AO16: 20 | AP16: 112 | AQ16: 237 | AR16: 272 | AS16: 281 | AW16: 326 | AX16: 833 | AY16: 236 | AZ16: 16 | BA16: 20 | BB16: 529 | BC16: 306 | BD16: 145 | BE16: 111 | BF16: 221 | BG16: 304 | BN16: 2432 | BO16: 137 | BQ16: 56 | BV16: 1825 | BW16: 135 | BX16: 65 | BZ16: 599 | CD16: 662 | CE16: 1163 | CF16: 502 | CG16: 89 | CH16: 819 | CI16: 380 | CJ16: 58 | CM16: 521 | CP16: 1050 | CQ16: 50 | CR16: 410 | CS16: 229 | CT16: 55 | CU16: 179 | CV16: 164 | CW16: 81 | CX16: 140 | CY16: 533 | CZ16: 261 | DB16: 500 | DE16: 1081 | DF16: 811 | DG16: =IFERROR(VLOOKUP(G16,Hoja2!$C$1:$E$1548,3,FALSE),0) -> 4 | DH16: =IFERROR(VLOOKUP(G16,Hoja2!$O$1:$P$1906,2,FALSE),0) -> 542
B17: VSF | D17: MANN-FILTER | E17: Pick up | F17: Cabin Filter | G17: CU 22 032 | H17: TOYOTA Hilux 2.4 TDI-2.8 TDI 2015Ã¢â€ â€™ | I17: 12 | K17: 10 | O17: 160 | P17: 330 | Q17: 265 | R17: 75 | S17: 9 | T17: 95 | U17: 185 | V17: 105 | W17: 50 | X17: 65 | Y17: 235 | Z17: 20 | AA17: 210 | AB17: 110 | AC17: -14 | AD17: 205 | AF17: 93 | AG17: 230 | AH17: 280 | AI17: 32 | AJ17: 286 | AK17: 225 | AM17: 250 | AN17: 200 | AP17: 235 | AQ17: 547 | AR17: 300 | AS17: 330 | AT17: 145 | AU17: 173 | AW17: 170 | AX17: 145 | AY17: 447 | AZ17: 515 | BA17: 130 | BB17: 136 | BC17: 527 | BD17: 305 | BE17: 505 | BF17: 440 | BG17: 165 | BH17: 43 | BI17: 452 | BJ17: 758 | BK17: 300 | BM17: 1460 | BN17: 770 | BP17: 135 | BQ17: 1265 | BR17: 1027 | BS17: 265 | BT17: 460 | BU17: 325 | BV17: 605 | BW17: 1174 | BX17: 425 | BY17: 446 | BZ17: 1665 | CA17: 1530 | CB17: 1347 | CC17: 785 | CD17: 845 | CE17: 1850 | CF17: 1055 | CG17: 760 | CH17: 2965 | CI17: 245 | CJ17: 1246 | CL17: 14 | CM17: 1701 | CN17: 2060 | CO17: 1630 | CP17: 50 | CQ17: 1150 | CR17: 445 | CS17: 1005 | CT17: 470 | CU17: 3070 | CV17: 1728 | CW17: 762 | CX17: 725 | CY17: 1778 | CZ17: 400 | DA17: 20 | DB17: 4200 | DC17: 1308 | DD17: 2250 | DE17: 922 | DF17: 558 | DG17: =IFERROR(VLOOKUP(G17,Hoja2!$C$1:$E$1548,3,FALSE),0) -> 842 | DH17: =IFERROR(VLOOKUP(G17,Hoja2!$O$1:$P$1906,2,FALSE),0) -> 2148
B18: VSF | D18: MANN-FILTER | E18: Pick up | F18: Cabin Filter | G18: CU 24 006 | H18: FORD Ranger 2012 2.2 TDCi, Ranger 2012 2.5 L, Ranger 2012 3.2 TDCi 11/12Ã¢â€ â€™ | I18: 12 | J18: 520 | K18: 202 | L18: 212 | M18: 24 | N18: 50 | O18: 52 | P18: 160 | Q18: 78 | R18: 106 | S18: 68 | T18: 254 | U18: 424 | V18: 248 | W18: 48 | X18: 252 | Y18: 268 | Z18: 54 | AA18: 32 | AB18: 84 | AC18: 86 | AD18: 282 | AE18: 112 | AF18: 20 | AG18: 198 | AH18: 514 | AI18: 253 | AJ18: 72 | AK18: 174 | AL18: 273 | AM18: 56 | AN18: 255 | AO18: 29 | AP18: 56 | AQ18: 633 | AR18: 372 | AS18: 320 | AT18: 184 | AU18: 170 | AV18: 87 | AW18: 125 | AX18: 330 | AY18: 97 | AZ18: 284 | BA18: 230 | BB18: 55 | BC18: 210 | BD18: 200 | BE18: 470 | BF18: 65 | BG18: 300 | BH18: 220 | BI18: 290 | BJ18: 105 | BK18: 355 | BL18: 25 | BM18: 530 | BN18: 460 | BP18: 72 | BQ18: 721 | BR18: 755 | BS18: 112 | BU18: 245 | BV18: 870 | BW18: 2 | BX18: 376 | BY18: 659 | BZ18: 855 | CA18: 118 | CB18: 275 | CC18: 1125 | CD18: 552 | CE18: 456 | CF18: 325 | CG18: 650 | CH18: 695 | CI18: 820 | CJ18: 3 | CM18: 757 | CN18: 1135 | CO18: 460 | CP18: 168 | CQ18: 412 | CR18: 425 | CS18: 360 | CT18: 205 | CU18: 190 | CV18: 720 | CW18: 345 | CX18: 220 | CY18: 635 | CZ18: 630 | DA18: 413 | DB18: 660 | DC18: 997 | DD18: 323 | DE18: 317 | DF18: 530 | DG18: =IFERROR(VLOOKUP(G18,Hoja2!$C$1:$E$1548,3,FALSE),0) -> 470 | DH18: =IFERROR(VLOOKUP(G18,Hoja2!$O$1:$P$1906,2,FALSE),0) -> 366
B19: VSF | D19: MANN-FILTER | E19: PC | F19: Cabin Filter | G19: CU 2442 | H19: Chevrolet Cruze 2.0 CDI, Cruze 1.8, Spin 1.8 8V - Cobalt 1.8 8V - Prisma 1.4 - Onix 1.4 - Cobalt 1.3 TD - Sonic 1.6 16V | I19: 12 | J19: 194 | K19: 300 | L19: 29 | M19: 8 | N19: 295 | O19: 203 | P19: 98 | Q19: 21 | R19: 141 | S19: 74 | T19: 187 | U19: 316 | V19: 44 | W19: 360 | X19: 380 | Y19: 139 | Z19: 172 | AA19: 88 | AB19: 40 | AC19: 141 | AD19: 217 | AE19: 96 | AF19: 263 | AG19: 152 | AH19: 385 | AI19: 289 | AJ19: 226 | AK19: 169 | AL19: 205 | AM19: 57 | AN19: 56 | AO19: 35 | AP19: 108 | AQ19: 343 | AR19: 290 | AS19: 396 | AT19: 160 | AU19: 99 | AV19: 44 | AW19: 114 | AX19: 127 | AY19: 234 | AZ19: 390 | BA19: 190 | BB19: 140 | BC19: 880 | BD19: 195 | BE19: 445 | BF19: 190 | BG19: 450 | BH19: 140 | BJ19: 505 | BK19: 205 | BL19: 120 | BM19: 625 | BN19: 230 | BO19: 135 | BP19: 65 | BQ19: 160 | BR19: 553 | BS19: 315 | BT19: 521 | BU19: 72 | BV19: 55 | BW19: 690 | BX19: 624 | BY19: 818 | BZ19: 202 | CA19: 228 | CB19: 612 | CC19: 1425 | CD19: 571 | CE19: 494 | CF19: 128 | CG19: 675 | CH19: 464 | CI19: 674 | CJ19: 21 | CK19: 50 | CL19: 13 | CM19: 487 | CN19: 535 | CO19: 180 | CP19: 360 | CQ19: 520 | CR19: 55 | CS19: 696 | CT19: 370 | CU19: 440 | CV19: 68 | CW19: 742 | CX19: 225 | CY19: 328 | CZ19: 450 | DA19: 625 | DB19: 999 | DC19: 700 | DD19: 440 | DE19: 475 | DF19: 30 | DG19: =IFERROR(VLOOKUP(G19,Hoja2!$C$1:$E$1548,3,FALSE),0) -> 737 | DH19: =IFERROR(VLOOKUP(G19,Hoja2!$O$1:$P$1906,2,FALSE),0) -> 243
B20: VSF | D20: MANN-FILTER | E20: PC | F20: Cabin Filter | G20: CU 25 007 | H20: FORD Kuga 2013 / FOCUS III 1.6 - 2.0 | I20: 12 | J20: 5 | O20: 265 | P20: 55 | Q20: 55 | R20: -1 | S20: 32 | T20: 30 | U20: 110 | V20: 1 | W20: 133 | X20: 92 | Z20: 4 | AA20: 85 | AB20: 28 | AC20: 40 | AD20: 55 | AF20: 70 | AG20: 65 | AH20: 84 | AI20: 117 | AJ20: 41 | AK20: 49 | AL20: 108 | AM20: 48 | AN20: 50 | AO20: 40 | AP20: 100 | AQ20: 80 | AR20: 91 | AS20: 148 | AT20: 42 | AU20: 31 | AV20: 14 | AW20: 46 | AX20: 252 | AY20: 206 | AZ20: 100 | BA20: 21 | BB20: 72 | BC20: 165 | BD20: 110 | BE20: 45 | BF20: 180 | BG20: 50 | BI20: 125 | BJ20: 271 | BK20: 210 | BL20: 174 | BM20: 146 | BN20: 160 | BO20: 95 | BP20: 15 | BQ20: 85 | BR20: 95 | BS20: 20 | BT20: 205 | BU20: 10 | BX20: 835 | BZ20: 340 | CA20: 250 | CB20: 240 | CC20: 95 | CD20: 270 | CE20: 129 | CF20: 309 | CG20: 140 | CH20: 375 | CI20: 145 | CJ20: 390 | CK20: 120 | CM20: 110 | CN20: 360 | CO20: 80 | CP20: 55 | CQ20: 174 | CR20: 116 | CS20: 30 | CT20: 284 | CU20: 71 | CV20: 169 | CW20: 50 | CX20: 140 | CY20: 345 | CZ20: 235 | DA20: 240 | DB20: 131 | DC20: 145 | DD20: 192 | DE20: 176 | DG20: =IFERROR(VLOOKUP(G20,Hoja2!$C$1:$E$1548,3,FALSE),0) -> 21 | DH20: =IFERROR(VLOOKUP(G20,Hoja2!$O$1:$P$1906,2,FALSE),0) -> 553
B21: VSF | D21: MANN-FILTER | E21: PC | F21: Cabin Filter | G21: CU 2629 | H21: Fiat Palio y Siena 1,0/1,3/1,6 1/200Ã¢â€ â€™ NÃ‚Â° 7082301 | I21: 12 | J21: 240 | K21: 210 | L21: 395 | M21: 60 | N21: 105 | O21: 20 | P21: 65 | R21: -20 | S21: 41 | T21: 120 | U21: 305 | V21: 195 | W21: 300 | X21: 310 | Y21: 175 | Z21: 162 | AA21: 57 | AC21: 203 | AD21: 5 | AE21: 40 | AF21: 40 | AG21: 270 | AH21: 140 | AI21: 216 | AJ21: 270 | AK21: 155 | AL21: 30 | AM21: 10 | AN21: 12 | AO21: 5 | AP21: 70 | AQ21: 130 | AR21: 151 | AS21: 166 | AT21: 95 | AU21: 97 | AV21: 25 | AW21: 58 | AX21: 50 | AY21: 146 | AZ21: 130 | BB21: 80 | BC21: 63 | BD21: 70 | BE21: 307 | BF21: 25 | BG21: 10 | BH21: 50 | BI21: 135 | BJ21: 90 | BK21: 195 | BM21: 185 | BN21: 430 | BO21: 10 | BP21: 25 | BQ21: 65 | BR21: 170 | BS21: 20 | BT21: 290 | BU21: 65 | BW21: 710 | BX21: 30 | BY21: 20 | BZ21: 210 | CA21: 160 | CB21: 50 | CC21: 175 | CD21: 135 | CE21: 165 | CF21: 105 | CG21: 195 | CI21: 385 | CJ21: 25 | CM21: 200 | CN21: 455 | CO21: 10 | CP21: 275 | CQ21: 74 | CR21: 160 | CS21: 90 | CT21: 35 | CU21: 60 | CV21: 145 | CW21: 90 | CX21: 60 | CY21: 209 | CZ21: 339 | DA21: 51 | DB21: 334 | DC21: 145 | DD21: 221 | DE21: 169 | DF21: 295 | DG21: =IFERROR(VLOOKUP(G21,Hoja2!$C$1:$E$1548,3,FALSE),0) -> 40 | DH21: =IFERROR(VLOOKUP(G21,Hoja2!$O$1:$P$1906,2,FALSE),0) -> 0
B22: VSF | D22: MANN-FILTER | E22: Pick up | F22: Cabin Filter | G22: CU 2842 | H22: VW Amarok | I22: 12 | J22: 185 | K22: 260 | L22: 527 | M22: 135 | N22: 55 | O22: 215 | P22: 155 | Q22: 90 | R22: 335 | S22: 171 | T22: 490 | U22: 62 | V22: 120 | W22: 838 | X22: 305 | Y22: 320 | Z22: 110 | AA22: 457 | AB22: 100 | AC22: 458 | AD22: 50 | AE22: 145 | AF22: 220 | AG22: 357 | AH22: 753 | AI22: 605 | AJ22: 90 | AK22: 265 | AL22: 95 | AM22: 205 | AN22: 120 | AO22: 30 | AP22: 220 | AQ22: 342 | AR22: 355 | AS22: 530 | AT22: 411 | AU22: 305 | AV22: 100 | AW22: 70 | AX22: 142 | AY22: 400 | AZ22: 564 | BA22: 42 | BB22: 198 | BC22: 422 | BD22: 320 | BE22: 310 | BF22: 320 | BG22: 390 | BH22: 520 | BI22: 480 | BJ22: 60 | BK22: 46 | BL22: 1266 | BM22: 1098 | BN22: 630 | BO22: 100 | BP22: 320 | BQ22: 140 | BR22: 980 | BS22: 310 | BT22: 160 | BU22: 40 | BV22: 90 | BW22: 1883 | BX22: 653 | BY22: 1274 | BZ22: 1634 | CA22: 896 | CB22: 559 | CC22: 990 | CD22: 1351 | CE22: 1352 | CF22: 830 | CG22: 840 | CH22: 1095 | CI22: 20 | CJ22: 1080 | CK22: 90 | CM22: 940 | CN22: 1610 | CO22: 290 | CP22: 350 | CQ22: 790 | CR22: 335 | CS22: 1320 | CT22: 280 | CU22: 2008 | CV22: 1082 | CW22: 100 | CX22: 370 | CY22: 1790 | CZ22: 390 | DA22: 1365 | DB22: 1737 | DC22: 860 | DD22: 1108 | DE22: 952 | DF22: 413 | DG22: =IFERROR(VLOOKUP(G22,Hoja2!$C$1:$E$1548,3,FALSE),0) -> 585 | DH22: =IFERROR(VLOOKUP(G22,Hoja2!$O$1:$P$1906,2,FALSE),0) -> 1333
B23: VSF | D23: MANN-FILTER | E23: PC | F23: Cabin Filter | G23: CU 2940 | H23: Citroen Aircross, C3, C4 2.0, Xsara Picasso, Peugeot 307,Partner 97Ã¢â€ â€™,GM Celta 1.4 - Citroen C4 Lounge 2.0 | I23: 12 | J23: 220 | K23: 350 | L23: 310 | M23: 80 | N23: 50 | O23: 115 | P23: 75 | Q23: 125 | R23: 85 | S23: 143 | T23: 215 | U23: 96 | V23: 314 | W23: 285 | X23: 240 | Y23: 180 | Z23: 275 | AA23: 210 | AC23: 195 | AD23: 150 | AF23: 85 | AG23: 155 | AH23: 348 | AI23: 270 | AJ23: 135 | AK23: 140 | AL23: 138 | AM23: 100 | AN23: 107 | AP23: 180 | AQ23: 273 | AR23: 180 | AS23: 259 | AT23: 92 | AU23: 110 | AV23: 60 | AW23: 20 | AX23: 106 | AY23: 148 | AZ23: 225 | BA23: 245 | BB23: 41 | BC23: 234 | BD23: 75 | BE23: 65 | BF23: 60 | BG23: 345 | BH23: 120 | BI23: 95 | BJ23: 150 | BK23: 135 | BL23: 35 | BM23: 490 | BN23: 370 | BP23: 40 | BQ23: 645 | BR23: 485 | BS23: 120 | BT23: 190 | BU23: 260 | BV23: 415 | BW23: 190 | BX23: 490 | BY23: 493 | BZ23: 351 | CA23: 750 | CB23: 246 | CC23: 149 | CD23: 260 | CE23: 362 | CF23: 325 | CG23: 365 | CH23: 288 | CI23: 490 | CJ23: 180 | CK23: 481 | CM23: 97 | CN23: 300 | CO23: 80 | CP23: 185 | CQ23: 159 | CR23: 220 | CS23: 135 | CT23: 130 | CU23: 180 | CV23: 380 | CW23: 90 | CX23: 260 | CY23: 277 | CZ23: 294 | DA23: 100 | DB23: 706 | DC23: 320 | DD23: 30 | DE23: 180 | DF23: 500 | DG23: =IFERROR(VLOOKUP(G23,Hoja2!$C$1:$E$1548,3,FALSE),0) -> 520 | DH23: =IFERROR(VLOOKUP(G23,Hoja2!$O$1:$P$1906,2,FALSE),0) -> 768
B24: VSF | D24: MANN-FILTER | E24: CV | F24: Cabin Filter | G24: CU 37 001 | H24: SCANIA P340 R340 R480 | I24: 12 | K24: 155 | L24: 100 | M24: 249 | N24: 46 | O24: 12 | P24: 279 | Q24: 14 | R24: 118 | S24: 52 | T24: 205 | U24: 156 | V24: 59 | W24: 246 | X24: 251 | Y24: 462 | Z24: 205 | AA24: 156 | AB24: -8 | AC24: 157 | AD24: 21 | AE24: 72 | AF24: 244 | AG24: 373 | AH24: 241 | AI24: 117 | AJ24: 110 | AK24: 240 | AL24: 106 | AM24: 114 | AN24: 175 | AP24: 203 | AQ24: 533 | AR24: 424 | AS24: 324 | AT24: 70 | AU24: 103 | AV24: 80 | AW24: 160 | AX24: 291 | AY24: 175 | AZ24: 190 | BA24: 140 | BB24: 295 | BC24: 17 | BD24: 530 | BE24: 723 | BF24: 210 | BG24: 450 | BH24: 60 | BI24: 47 | BJ24: 383 | BK24: 675 | BL24: 27 | BM24: 170 | BN24: 365 | BP24: 258 | BQ24: 657 | BR24: 153 | BS24: 320 | BT24: 130 | BU24: 340 | BV24: 310 | BW24: 95 | BX24: 175 | BY24: 195 | BZ24: 835 | CA24: 290 | CB24: 170 | CC24: 360 | CD24: 185 | CE24: 240 | CF24: 592 | CG24: 178 | CH24: 225 | CI24: 460 | CJ24: 185 | CM24: 350 | CN24: 457 | CO24: 110 | CP24: 563 | CQ24: 190 | CR24: 285 | CS24: 480 | CT24: 90 | CU24: 230 | CV24: 125 | CW24: 130 | CX24: 360 | CY24: 335 | CZ24: 370 | DA24: 152 | DB24: 288 | DC24: 120 | DD24: 190 | DE24: 220 | DF24: 285 | DG24: =IFERROR(VLOOKUP(G24,Hoja2!$C$1:$E$1548,3,FALSE),0) -> 125 | DH24: =IFERROR(VLOOKUP(G24,Hoja2!$O$1:$P$1906,2,FALSE),0) -> 170
B25: VSF | D25: MANN-FILTER | E25: CV | F25: Cabin Filter | G25: CU 5877 | H25: Mercedes Benz Atego 1725 | I25: 12 | K25: 37 | L25: 20 | M25: 20 | N25: 25 | O25: 24 | P25: 6 | Q25: 13 | R25: -28 | S25: 38 | T25: 62 | U25: 35 | V25: 39 | W25: 71 | X25: 14 | Y25: 19 | Z25: 61 | AA25: 64 | AB25: 17 | AC25: 20 | AD25: 65 | AF25: 70 | AG25: 70 | AH25: 52 | AI25: 52 | AJ25: 37 | AK25: 40 | AL25: 45 | AM25: 80 | AN25: 101 | AO25: 37 | AP25: 28 | AQ25: 92 | AR25: 73 | AS25: 45 | AT25: 216 | AU25: 60 | AW25: 5 | AX25: 130 | AY25: 137 | AZ25: 128 | BA25: 80 | BB25: 50 | BC25: 183 | BD25: 120 | BE25: 100 | BF25: 20 | BG25: 106 | BI25: 36 | BJ25: 200 | BK25: 10 | BL25: 250 | BM25: 473 | BN25: 95 | BO25: 25 | BP25: 5 | BQ25: 115 | BR25: 50 | BS25: 60 | BT25: 65 | BU25: 268 | BV25: 132 | BW25: 115 | BX25: 115 | BY25: 40 | BZ25: 250 | CA25: 190 | CB25: 270 | CC25: 85 | CD25: 5 | CE25: 40 | CF25: 95 | CG25: 275 | CH25: 240 | CI25: 17 | CM25: 348 | CN25: 365 | CO25: 35 | CP25: 667 | CQ25: 90 | CR25: 250 | CS25: 283 | CT25: 40 | CU25: 120 | CV25: 130 | CW25: 110 | CX25: 140 | CY25: 230 | CZ25: 70 | DB25: 2 | DD25: 568 | DE25: 31 | DF25: 279 | DG25: =IFERROR(VLOOKUP(G25,Hoja2!$C$1:$E$1548,3,FALSE),0) -> 202 | DH25: =IFERROR(VLOOKUP(G25,Hoja2!$O$1:$P$1906,2,FALSE),0) -> 33
B26: VSF | D26: MANN-FILTER | E26: PC | F26: Cabin Filter | G26: CUK 20 011 | H26: FIAT Palio 1.4 8V Evo-1.6 E-TORQ-Uno 1.4 EVO 8V Fire | I26: 12 | J26: 4 | K26: 165 | L26: 35 | O26: 90 | P26: 57 | Q26: 51 | R26: 16 | S26: 12 | T26: 5 | U26: 205 | W26: 178 | X26: 97 | AL26: 761 | AN26: 272 | AP26: 21 | AQ26: 86 | AR26: 35 | AS26: 41 | AU26: 9 | AW26: 18 | AX26: 223 | AY26: 28 | AZ26: 19 | BA26: 12 | BB26: 41 | BC26: 142 | BD26: 94 | BE26: 70 | BF26: 19 | BG26: 110 | BN26: 1563 | BV26: 914 | BW26: 1005 | BY26: 4 | BZ26: 8 | CB26: 545 | CC26: 1093 | CD26: 180 | CE26: 510 | CF26: 79 | CG26: 901 | CH26: 595 | CI26: 290 | CJ26: 73 | CN26: 758 | CO26: 420 | CP26: 110 | CQ26: 357 | CR26: 250 | CS26: 270 | CT26: 207 | CU26: 140 | CV26: 405 | CW26: 101 | CX26: 285 | CY26: 233 | DA26: 687 | DB26: 260 | DC26: 1265 | DD26: 416 | DE26: 474 | DF26: 1 | DG26: =IFERROR(VLOOKUP(G26,Hoja2!$C$1:$E$1548,3,FALSE),0) -> 999 | DH26: =IFERROR(VLOOKUP(G26,Hoja2!$O$1:$P$1906,2,FALSE),0) -> 1140
B27: VSF | D27: MANN-FILTER | E27: PC | F27: Cabin Filter | G27: CUK 26 009 | H27: AUDI A3 1.4-1.8 TFSI - 2.0 TDI / VW Golf VII 1.4 TSI-1.6 MSI -2.0 GTI | I27: 12 | J27: 20 | K27: 12 | M27: 12 | N27: 8 | O27: 20 | P27: 8 | Q27: 24 | R27: 4 | S27: 32 | T27: 16 | U27: 52 | V27: 20 | W27: 12 | X27: 52 | Y27: 52 | AB27: 8 | AC27: 32 | AD27: 17 | AE27: 12 | AF27: 12 | AG27: 106 | AH27: 64 | AI27: 52 | AJ27: 137 | AK27: 44 | AL27: 79 | AM27: 16 | AO27: 50 | AQ27: 104 | AR27: 50 | AS27: 93 | AT27: 29 | AW27: 96 | AX27: 62 | AY27: 62 | AZ27: 171 | BA27: 84 | BB27: 5 | BC27: 165 | BD27: 91 | BE27: 113 | BF27: 85 | BG27: 100 | BJ27: 25 | BL27: 290 | BM27: 96 | BN27: 100 | BP27: 40 | BQ27: 170 | BR27: 205 | BS27: 36 | BT27: 5 | BV27: 200 | BW27: 230 | BX27: 155 | BY27: 195 | BZ27: 575 | CA27: 490 | CB27: 27 | CC27: 691 | CD27: 20 | CE27: 484 | CG27: 250 | CH27: 101 | CI27: 142 | CJ27: 191 | CK27: 270 | CL27: 70 | CM27: 190 | CN27: 165 | CO27: 200 | CP27: 40 | CQ27: 100 | CR27: 70 | CS27: 140 | CT27: 100 | CU27: 45 | CV27: 130 | CW27: 65 | CX27: 65 | CY27: 275 | CZ27: 260 | DA27: 235 | DB27: 105 | DC27: 17 | DD27: 210 | DE27: 278 | DF27: 114 | DG27: =IFERROR(VLOOKUP(G27,Hoja2!$C$1:$E$1548,3,FALSE),0) -> 168 | DH27: =IFERROR(VLOOKUP(G27,Hoja2!$O$1:$P$1906,2,FALSE),0) -> 172
B28: VSF | D28: MANN-FILTER | E28: PC | F28: Oil Filter | G28: HU 6006 Z | H28: Toyota corolla 1.8 2012Ã¢â€ â€™/ rav 4 /prius (Reemplaza a HU 6006 x) | I28: 12 | J28: 1910 | K28: 220 | L28: 170 | M28: 695 | N28: 1010 | O28: 195 | P28: 265 | Q28: 730 | R28: 350 | S28: 87 | T28: 480 | U28: 175 | V28: 460 | W28: 595 | X28: 272 | Y28: 923 | Z28: 1098 | AA28: 330 | AB28: 256 | AC28: 50 | AD28: 901 | AE28: 29 | AF28: 1035 | AG28: 430 | AH28: 2195 | AI28: 164 | AJ28: 426 | AK28: 47 | AW28: 435 | AX28: 1110 | AY28: 1470 | AZ28: 330 | BA28: 611 | BB28: 813 | BD28: 678 | BE28: 690 | BF28: 1560 | BG28: 1022 | BH28: 234 | BI28: 413 | BJ28: 470 | BK28: 953 | BL28: 817 | BM28: 1310 | BN28: 1071 | BO28: 19 | BP28: 1419 | BQ28: 632 | BR28: 1000 | BS28: 970 | BT28: 738 | BU28: 590 | BV28: 580 | BW28: 1232 | BX28: 690 | BY28: 1440 | BZ28: 760 | CA28: 1310 | CB28: 508 | CC28: 1302 | CD28: 740 | CE28: 1270 | CF28: 257 | CG28: 2023 | CH28: 127 | CI28: 1759 | CJ28: 900 | CL28: 1280 | CM28: 1540 | CN28: 1751 | CO28: 98 | CP28: 2639 | CQ28: 320 | CR28: 160 | CS28: 2183 | CT28: 400 | CU28: 410 | CV28: 1450 | CW28: 1830 | CX28: 760 | CY28: 130 | CZ28: 271 | DA28: 360 | DB28: 190 | DC28: 3250 | DD28: 1320 | DE28: 28 | DF28: 640 | DG28: =IFERROR(VLOOKUP(G28,Hoja2!$C$1:$E$1548,3,FALSE),0) -> 1135 | DH28: =IFERROR(VLOOKUP(G28,Hoja2!$O$1:$P$1906,2,FALSE),0) -> 450
B29: VSF | D29: MANN-FILTER | E29: PC | F29: Oil Filter | G29: HU 6011 Z | H29: RENAULT Master III 2.3 Dci 2013Ã¢â€ â€™ / MERCEDES-BENZ VITO 2015 Ã¢â€ â€™ NISSAN Frontier 2.3 dCi NP300 2016Ã¢â€ â€™ /Renault Alaskan | I29: 12 | J29: 40 | K29: 85 | L29: 40 | M29: 90 | N29: 125 | O29: 60 | P29: 50 | Q29: 55 | R29: 70 | S29: 137 | T29: 113 | U29: 60 | W29: 200 | X29: 217 | Y29: 85 | Z29: 110 | AA29: 218 | AC29: 180 | AD29: 240 | AE29: 70 | AF29: 234 | AG29: 98 | AH29: 186 | AI29: 140 | AJ29: 172 | AK29: 455 | AL29: 143 | AM29: 107 | AN29: 271 | AO29: 164 | AP29: 218 | AQ29: 160 | AR29: 190 | AS29: 158 | AT29: 174 | AU29: 606 | AV29: 19 | AW29: 106 | AX29: 220 | AY29: 290 | AZ29: 140 | BA29: 255 | BB29: 134 | BC29: 400 | BD29: 420 | BE29: 361 | BF29: 280 | BG29: 119 | BH29: 110 | BI29: 120 | BJ29: 350 | BM29: 530 | BN29: 1226 | BP29: 74 | BQ29: 987 | BR29: 260 | BS29: 353 | BT29: 884 | BU29: 466 | BV29: 434 | BW29: 336 | BX29: 204 | BY29: 756 | BZ29: 1140 | CA29: 564 | CB29: 414 | CC29: 235 | CD29: 440 | CE29: 717 | CF29: 350 | CG29: 790 | CH29: 440 | CI29: 573 | CJ29: 157 | CM29: 995 | CN29: 920 | CO29: 180 | CP29: 840 | CQ29: 310 | CR29: 260 | CS29: 620 | CT29: 450 | CU29: 360 | CV29: 720 | CW29: 370 | CX29: 570 | CY29: 432 | CZ29: 513 | DA29: 397 | DB29: 700 | DC29: 640 | DD29: 560 | DE29: 803 | DF29: 200 | DG29: =IFERROR(VLOOKUP(G29,Hoja2!$C$1:$E$1548,3,FALSE),0) -> 400 | DH29: =IFERROR(VLOOKUP(G29,Hoja2!$O$1:$P$1906,2,FALSE),0) -> 1230
B30: VSF | D30: MANN-FILTER | E30: PC | F30: Oil Filter | G30: HU 6013 z | H30: AUDI A3 TFSI 1.8 180 CV - Q5 2.0 TFSI 225CV - VW VENTO 2.0 TSI 2013Ã¢â€ â€™ VW GOLF 2.0 GTI 2013Ã¢â€ â€™ (Reemplaza a HU 6002 z) | I30: 12 | AL30: 100 | AM30: 46 | AN30: 94 | AO30: 312 | AP30: 164 | AQ30: 20 | AR30: 158 | AS30: 92 | AT30: 154 | AU30: 27 | AV30: 7 | AW30: 86 | AX30: 110 | AY30: 307 | AZ30: 141 | BA30: 152 | BB30: 167 | BC30: 72 | BD30: 99 | BE30: 10 | BF30: 170 | BG30: 12 | BH30: 530 | BI30: 199 | BJ30: 289 | BK30: 152 | BL30: 146 | BM30: 172 | BN30: 441 | BP30: 35 | BQ30: 428 | BR30: 237 | BT30: 590 | BU30: 130 | BV30: 311 | BW30: 622 | BX30: 152 | BY30: 312 | BZ30: 222 | CA30: 414 | CB30: 374 | CC30: 122 | CD30: 354 | CE30: 206 | CF30: 152 | CG30: 526 | CH30: 214 | CI30: 386 | CJ30: 134 | CM30: 592 | CN30: 362 | CO30: 206 | CP30: 650 | CQ30: 134 | CR30: 60 | CS30: 92 | CT30: 78 | CU30: 290 | CV30: 402 | CW30: 276 | CX30: 322 | CY30: 247 | CZ30: 309 | DB30: 594 | DC30: 312 | DD30: 292 | DE30: 190 | DF30: 212 | DG30: =IFERROR(VLOOKUP(G30,Hoja2!$C$1:$E$1548,3,FALSE),0) -> 200 | DH30: =IFERROR(VLOOKUP(G30,Hoja2!$O$1:$P$1906,2,FALSE),0) -> 390
B31: VSF | D31: MANN-FILTER | E31: PC | F31: Oil Filter | G31: HU 612/2 x | H31: Chevrolet Cruze 1.8, Sonic 1.6 16V | I31: 12 | J31: 600 | K31: 360 | L31: 1002 | M31: 120 | N31: 998 | O31: 254 | P31: 1288 | Q31: 612 | R31: 420 | S31: 526 | T31: 514 | U31: 1200 | W31: 1470 | X31: 1480 | Y31: 1068 | Z31: 502 | AA31: 1200 | AB31: 560 | AC31: 594 | AD31: 1628 | AE31: 370 | AF31: 489 | AG31: 230 | AH31: 724 | AI31: 3612 | AJ31: 328 | AK31: 479 | AL31: 486 | AM31: 193 | AN31: 1114 | AO31: 338 | AP31: 266 | AQ31: 2050 | AR31: 770 | AS31: 276 | AT31: 1114 | AU31: 298 | AV31: 832 | AW31: 210 | AX31: 1034 | AY31: 210 | AZ31: 660 | BA31: 340 | BB31: 1800 | BC31: 330 | BD31: 461 | BE31: 984 | BF31: 1130 | BG31: 890 | BH31: 910 | BI31: 449 | BJ31: 765 | BK31: 1250 | BL31: 161 | BM31: 646 | BN31: 1765 | BO31: 235 | BP31: 635 | BQ31: 1600 | BR31: 816 | BS31: 1388 | BT31: 3144 | BU31: 1896 | BV31: 300 | BW31: 1718 | BX31: 647 | BY31: 1687 | BZ31: 1200 | CA31: 1508 | CB31: 1236 | CC31: 412 | CD31: 970 | CE31: 1126 | CF31: 1700 | CG31: 662 | CH31: 1288 | CI31: 1292 | CJ31: 742 | CK31: 48 | CL31: 1080 | CM31: 742 | CN31: 1940 | CO31: 570 | CP31: 850 | CQ31: 1051 | CR31: 910 | CS31: 825 | CT31: 680 | CU31: 370 | CV31: 1620 | CW31: 551 | CX31: 1435 | CY31: 160 | CZ31: 580 | DA31: 485 | DB31: 2330 | DD31: 500 | DF31: 1981 | DG31: =IFERROR(VLOOKUP(G31,Hoja2!$C$1:$E$1548,3,FALSE),0) -> 1600 | DH31: =IFERROR(VLOOKUP(G31,Hoja2!$O$1:$P$1906,2,FALSE),0) -> 620
B32: VSF | D32: MANN-FILTER | E32: Pick up | F32: Oil Filter | G32: HU 7002 Z | H32: FORD RANGER NUEVA 2,2 TDCi 125cv 2012 Ã¢â€ â€™, 3,2 TDCi 200cv 2012 Ã¢â€ â€™ | I32: 12 | J32: 72 | K32: 1080 | L32: 1020 | M32: 156 | N32: 200 | O32: 432 | P32: 1332 | Q32: 510 | R32: 808 | S32: 372 | T32: 326 | U32: 104 | V32: 100 | W32: 620 | X32: 1298 | Y32: 1106 | Z32: 378 | AA32: 834 | AB32: 586 | AC32: 92 | AD32: 1356 | AE32: 739 | AF32: 444 | AI32: 1596 | AJ32: 1847 | AK32: 662 | AL32: 212 | AM32: 2016 | AN32: 448 | AO32: 124 | AP32: 660 | AQ32: 2006 | AR32: 714 | AS32: 266 | AT32: 287 | AU32: 988 | AV32: 135 | AW32: 150 | AX32: 640 | AY32: 1070 | AZ32: 370 | BA32: 1340 | BB32: 560 | BC32: 490 | BD32: 750 | BE32: 921 | BF32: 880 | BI32: 3450 | BJ32: 369 | BK32: 1481 | BL32: 949 | BM32: 1240 | BN32: 1371 | BQ32: 2080 | BR32: 3335 | BS32: 575 | BT32: 1450 | BU32: 2440 | BV32: 110 | BW32: 1490 | BX32: 930 | BY32: 1090 | BZ32: 1770 | CA32: 1490 | CB32: 1450 | CC32: 770 | CD32: 1930 | CE32: 1540 | CF32: 2075 | CG32: 390 | CH32: 1870 | CI32: 820 | CL32: 1230 | CM32: 2065 | CN32: 2360 | CO32: 555 | CP32: 1400 | CQ32: 1367 | CR32: 1743 | CS32: 895 | CT32: 1100 | CU32: 1170 | CV32: 3560 | CW32: 180 | CX32: 2210 | CY32: 440 | CZ32: 730 | DA32: 840 | DB32: 1030 | DC32: 1270 | DD32: 2130 | DE32: 552 | DF32: 2061 | DG32: =IFERROR(VLOOKUP(G32,Hoja2!$C$1:$E$1548,3,FALSE),0) -> 602 | DH32: =IFERROR(VLOOKUP(G32,Hoja2!$O$1:$P$1906,2,FALSE),0) -> 2042
B33: VSF | D33: MANN-FILTER | E33: Pick up | F33: Oil Filter | G33: HU 7008 z | H33: VW Amarok 2,0 td 2010 Ã¢â€ â€™ (oem VW 03L115562) | I33: 12 | J33: 3125 | K33: 870 | L33: 991 | N33: 2361 | O33: 889 | P33: 2525 | Q33: 1402 | R33: 542 | S33: 1588 | T33: 2580 | U33: 570 | V33: 583 | W33: 1040 | X33: 1490 | Y33: 2060 | Z33: 2778 | AA33: 922 | AB33: 500 | AC33: 863 | AD33: 4560 | AE33: 170 | AF33: 3408 | AG33: 1080 | AH33: 792 | AI33: 1004 | AJ33: 1804 | AK33: 705 | AL33: 948 | AM33: 1954 | AN33: 684 | AO33: 1312 | AP33: 864 | AQ33: 2510 | AR33: 1496 | AS33: 1480 | AT33: 1767 | AU33: 300 | AV33: 2003 | AW33: 500 | AX33: 1099 | AY33: 1280 | AZ33: 1560 | BA33: 1012 | BB33: 1267 | BC33: 2083 | BD33: 750 | BE33: 1420 | BF33: 1550 | BG33: 800 | BH33: 1030 | BI33: 1270 | BJ33: 1981 | BK33: 880 | BL33: 2700 | BM33: 1200 | BN33: 85 | BP33: 1095 | BQ33: 2502 | BR33: 870 | BS33: 1342 | BT33: 1200 | BU33: 500 | BV33: 2891 | BW33: 1648 | BX33: 1211 | BY33: 2740 | BZ33: 2040 | CA33: 3080 | CB33: 2430 | CC33: 1580 | CD33: 2610 | CE33: 3884 | CF33: 2050 | CG33: 3680 | CH33: 1396 | CI33: 610 | CJ33: 1071 | CL33: 1800 | CM33: 2900 | CN33: 3199 | CO33: 1260 | CP33: 1651 | CQ33: 2239 | CR33: 811 | CS33: 5155 | CT33: 510 | CU33: 2370 | CV33: 2010 | CW33: 2905 | CX33: 2610 | CY33: 890 | CZ33: 320 | DA33: 1560 | DB33: 1610 | DC33: 1205 | DD33: 3710 | DE33: 1230 | DF33: 1500 | DG33: =IFERROR(VLOOKUP(G33,Hoja2!$C$1:$E$1548,3,FALSE),0) -> 1412 | DH33: =IFERROR(VLOOKUP(G33,Hoja2!$O$1:$P$1906,2,FALSE),0) -> 2240
B34: VSF | D34: MANN-FILTER | E34: PC | F34: Oil Filter | G34: HU 7010 Z | H34: MERCEDES BENZ A-Klasse A 180 CDI 1.8 B-Klasse B 180 CDI C-Klasse C 180 CDI Sprinter II 210 CDI- JEEP Compass 2.2 CRD Patriot 2.2 CRD Sprinter II 210 CDI | I34: 12 | J34: 410 | K34: 145 | L34: 395 | M34: 420 | N34: 295 | O34: 654 | P34: 656 | Q34: 255 | R34: 489 | S34: 260 | T34: 330 | U34: 30 | V34: 70 | W34: 1200 | X34: 480 | Y34: 820 | Z34: 730 | AA34: 710 | AB34: 695 | AC34: 75 | AD34: 1460 | AE34: 225 | AF34: 585 | AG34: 675 | AH34: 950 | AI34: 689 | AJ34: 645 | AK34: 675 | AL34: 796 | AM34: 700 | AN34: 1090 | AO34: 810 | AP34: 700 | AQ34: 614 | AR34: 726 | AS34: 510 | AT34: 895 | AU34: 45 | AV34: 5 | AW34: 721 | AX34: 1360 | AY34: 325 | AZ34: 290 | BA34: 865 | BB34: 564 | BC34: 170 | BD34: 636 | BE34: 424 | BF34: 866 | BG34: 490 | BH34: 320 | BI34: 410 | BJ34: 550 | BK34: 1190 | BL34: 4 | BM34: 350 | BP34: 380 | BQ34: 1666 | BR34: 44 | BS34: 1530 | BT34: 1600 | BU34: 730 | BV34: 690 | BW34: 480 | BX34: 490 | BY34: 570 | BZ34: 570 | CA34: 550 | CB34: 1280 | CC34: 600 | CD34: 1080 | CE34: 1500 | CF34: 820 | CG34: 590 | CH34: 660 | CI34: 880 | CJ34: 880 | CM34: 1410 | CN34: 1460 | CO34: 80 | CP34: 1040 | CQ34: 560 | CR34: 700 | CS34: 600 | CT34: 330 | CU34: 450 | CV34: 460 | CW34: 400 | CX34: 740 | CY34: 600 | CZ34: 490 | DA34: 450 | DB34: 620 | DC34: 700 | DD34: 630 | DE34: 928 | DF34: 532 | DG34: =IFERROR(VLOOKUP(G34,Hoja2!$C$1:$E$1548,3,FALSE),0) -> 90 | DH34: =IFERROR(VLOOKUP(G34,Hoja2!$O$1:$P$1906,2,FALSE),0) -> 480
B35: VSF | D35: MANN-FILTER | E35: PC | F35: Oil Filter | G35: HU 7012 Z | H35: AUDI Q7 3.0 TDI 2016Ã¢â€ â€™, VW Amarok 3.0 V6 225 CV | I35: 12 | Z35: 10 | AC35: 8 | AF35: 24 | AG35: 100 | AI35: 418 | AJ35: 56 | AK35: 45 | AM35: 38 | AN35: 38 | AO35: 88 | AP35: 41 | AR35: 33 | AS35: 37 | AT35: 22 | AU35: 49 | AV35: 35 | AW35: 5 | AX35: 12 | AY35: 55 | AZ35: 82 | BB35: 86 | BC35: 75 | BD35: 86 | BE35: 268 | BF35: 118 | BI35: 306 | BJ35: 232 | BK35: 66 | BM35: 218 | BN35: 20 | BP35: 440 | BQ35: 264 | BR35: 154 | BS35: 138 | BT35: 258 | BU35: 137 | BW35: 900 | BX35: 357 | BY35: 556 | BZ35: 192 | CA35: 544 | CC35: 298 | CD35: 354 | CE35: 460 | CF35: 270 | CG35: 178 | CH35: 238 | CI35: 440 | CM35: 1024 | CN35: 612 | CO35: 310 | CP35: 492 | CQ35: 338 | CR35: 304 | CS35: 726 | CT35: 82 | CU35: 532 | CV35: 550 | CW35: 245 | CX35: 904 | CY35: 719 | CZ35: 398 | DA35: 401 | DB35: 1544 | DC35: 50 | DD35: 1339 | DE35: 564 | DF35: 665 | DG35: =IFERROR(VLOOKUP(G35,Hoja2!$C$1:$E$1548,3,FALSE),0) -> 238 | DH35: =IFERROR(VLOOKUP(G35,Hoja2!$O$1:$P$1906,2,FALSE),0) -> 1114
B36: VSF | D36: MANN-FILTER | E36: PC | F36: Oil Filter | G36: HU 711/51 X | H36: Peugeot/Citroen Varios; Peugeot 407 2005 2.0 HDI; N* Orig. Citroen 1109-X4/1109-Z2, Peugeot 1109-X3/Z1; Volvo 30650798; Ford 1303476, Peugeot 207 1.6 16V, Fiat Qubo 1.4 8V - Citroen C4 Lounge 2.0 - Peugeot 208 1.5 8V | I36: 12 | J36: 7650 | K36: 6790 | L36: 6185 | M36: 3280 | O36: 2010 | P36: 12590 | Q36: 5550 | R36: 1230 | S36: 4610 | T36: 5180 | U36: 3690 | V36: 4250 | W36: 1238 | X36: 3460 | Y36: 6790 | Z36: 5090 | AA36: 8925 | AB36: 2170 | AC36: 5045 | AD36: 5135 | AE36: 150 | AF36: 11269 | AG36: 1111 | AH36: 9679 | AI36: 3072 | AJ36: 5960 | AK36: 1295 | AL36: 4866 | AM36: 1124 | AN36: 6129 | AO36: 1602 | AP36: 4950 | AQ36: 1308 | AR36: 6872 | AS36: 1932 | AT36: 2620 | AU36: 8606 | AV36: 1143 | AW36: 1300 | AX36: 2400 | AY36: 608 | AZ36: 1802 | BA36: 4190 | BB36: 3780 | BC36: 4702 | BD36: 2153 | BE36: 3612 | BF36: 242 | BG36: 4120 | BH36: 8301 | BI36: 1700 | BJ36: 1699 | BK36: 7923 | BL36: 6289 | BM36: 11560 | BN36: 1652 | BO36: 2700 | BP36: 3150 | BQ36: 2750 | BR36: 8895 | BS36: 3212 | BT36: 2861 | BU36: 8850 | BV36: 1980 | BW36: 900 | BX36: 1700 | BY36: 2488 | BZ36: 4550 | CA36: 3740 | CB36: 5490 | CC36: 3350 | CD36: 2500 | CE36: 8108 | CF36: 1942 | CG36: 4356 | CH36: 4592 | CI36: 2926 | CJ36: 4724 | CL36: 6900 | CM36: 5466 | CN36: 9290 | CO36: 2140 | CP36: 5848 | CQ36: 2624 | CR36: 3428 | CS36: 13503 | CT36: 1440 | CU36: 5404 | CV36: 3420 | CW36: 9907 | CX36: 6481 | CY36: 3580 | CZ36: 3560 | DA36: 3185 | DB36: 9199 | DC36: 3696 | DD36: 4300 | DE36: 3570 | DF36: 2111 | DG36: =IFERROR(VLOOKUP(G36,Hoja2!$C$1:$E$1548,3,FALSE),0) -> 3097 | DH36: =IFERROR(VLOOKUP(G36,Hoja2!$O$1:$P$1906,2,FALSE),0) -> 2640
B37: VSF | D37: MANN-FILTER | E37: PC | F37: Oil Filter | G37: HU 711/6 Z | H37: MERCEDES-BENZ Clase A-B-CLA-E BlueEFFICIENCY M 270(Reemplaza a HU 7044 z) | I37: 12 | J37: 80 | K37: 100 | N37: 150 | O37: 12 | P37: 118 | Q37: 30 | S37: 42 | T37: 152 | U37: 10 | V37: 146 | W37: 10 | X37: 88 | Y37: 2 | Z37: -2 | AA37: 2 | AB37: 240 | AC37: -2 | BA37: 275 | BB37: 86 | BC37: 70 | BD37: 86 | BE37: 192 | BF37: 223 | BH37: 220 | BI37: 320 | BJ37: 509 | BK37: 116 | BL37: 34 | BM37: 180 | BN37: 150 | BP37: 360 | BQ37: 466 | BR37: 226 | BS37: 168 | BT37: 128 | BU37: 134 | BV37: 272 | BW37: 116 | BX37: 164 | BY37: 158 | BZ37: 180 | CA37: 102 | CB37: 158 | CC37: 46 | CD37: 300 | CE37: 183 | CF37: 120 | CG37: 130 | CH37: 300 | CI37: 75 | CJ37: 128 | CK37: 20 | CM37: 120 | CN37: 112 | CO37: 258 | CP37: 294 | CQ37: 28 | CR37: 139 | CS37: 77 | CT37: 32 | CU37: 116 | CV37: 70 | CW37: 112 | CX37: 98 | CY37: 52 | CZ37: 104 | DA37: 76 | DB37: 92 | DC37: 64 | DD37: 106 | DE37: 178 | DF37: 188 | DG37: =IFERROR(VLOOKUP(G37,Hoja2!$C$1:$E$1548,3,FALSE),0) -> 4 | DH37: =IFERROR(VLOOKUP(G37,Hoja2!$O$1:$P$1906,2,FALSE),0) -> 174
B38: VSF | D38: MANN-FILTER | E38: PC | F38: Oil Filter | G38: HU 716/2 X | H38: Citroen C3, Xsara, Ford Fiesta NÃ‚Â° orig. Citroen 1109-s5/1109-T3 Ford 1147685 | I38: 12 | J38: 1224 | K38: 1152 | L38: 1200 | M38: 748 | N38: 550 | O38: 600 | P38: 2467 | Q38: 438 | R38: 1014 | S38: 524 | T38: 761 | U38: 24 | V38: 2055 | W38: 93 | X38: 1402 | Y38: 2750 | Z38: 127 | AA38: 1499 | AB38: 884 | AC38: 1150 | AD38: 1524 | AE38: 306 | AF38: 947 | AG38: 589 | AH38: 624 | AI38: 682 | AJ38: 578 | AK38: 1555 | AM38: 2017 | AN38: 749 | AO38: 353 | AP38: 1320 | AQ38: 678 | AR38: 813 | AS38: 332 | AT38: 1490 | AU38: 617 | AW38: 1341 | AX38: 1200 | AY38: 436 | AZ38: 800 | BA38: 760 | BB38: 980 | BC38: 440 | BD38: 240 | BE38: 810 | BF38: 580 | BG38: 1300 | BH38: 841 | BI38: 940 | BJ38: 660 | BK38: 1260 | BL38: 420 | BM38: 420 | BN38: 301 | BO38: 14 | BP38: 30 | BQ38: 1621 | BR38: 489 | BS38: 1090 | BT38: 2136 | BU38: 2134 | BV38: 1065 | BW38: 1965 | BX38: 1256 | BY38: 1240 | BZ38: 1340 | CA38: 1660 | CB38: 1560 | CC38: 620 | CD38: 830 | CE38: 1140 | CF38: 1220 | CG38: 1040 | CH38: 1210 | CI38: 1780 | CJ38: 2105 | CM38: 2210 | CO38: 1585 | CP38: 1015 | CQ38: 1340 | CR38: 1150 | CS38: 520 | CT38: 600 | CU38: 700 | CV38: 3111 | CW38: 952 | CX38: 120 | CY38: 986 | CZ38: 734 | DA38: 36 | DB38: 2084 | DC38: 916 | DD38: 600 | DE38: 1500 | DF38: 700 | DG38: =IFERROR(VLOOKUP(G38,Hoja2!$C$1:$E$1548,3,FALSE),0) -> 237 | DH38: =IFERROR(VLOOKUP(G38,Hoja2!$O$1:$P$1906,2,FALSE),0) -> 1860
B39: VSF | D39: MANN-FILTER | E39: PC | F39: Oil Filter | G39: HU 718/1 K | H39: MERCEDES-BENZ Sprinter 311-313-413 CDI - C-Klasse 220 CDI- E-Klasse 220 CDI- Viano 2.0 CDI | I39: 12 | J39: 520 | K39: 510 | L39: 810 | M39: 589 | N39: 50 | O39: 300 | P39: 1430 | Q39: 586 | R39: 410 | S39: 416 | T39: 320 | U39: 520 | V39: 998 | W39: 150 | X39: 680 | Y39: 730 | Z39: 901 | AA39: 624 | AB39: 154 | AC39: 490 | AD39: 1450 | AE39: 30 | AF39: 637 | AG39: 380 | AH39: 550 | AI39: 511 | AJ39: 820 | AK39: 295 | AL39: 596 | AM39: 390 | AN39: 556 | AO39: 258 | AP39: 210 | AQ39: 407 | AR39: 304 | AS39: 233 | AT39: 260 | AU39: 490 | AV39: 212 | AW39: 148 | AX39: 90 | AY39: 270 | AZ39: 570 | BA39: 10 | BC39: 630 | BD39: 371 | BE39: 590 | BF39: 470 | BG39: 380 | BH39: 180 | BI39: 201 | BJ39: 500 | BK39: 110 | BL39: 520 | BM39: 250 | BN39: 291 | BO39: 157 | BP39: 323 | BQ39: 287 | BR39: 460 | BS39: 480 | BT39: 620 | BU39: 593 | BV39: 147 | BW39: 430 | BX39: 150 | BY39: 533 | CA39: 780 | CB39: 243 | CD39: 720 | CE39: 450 | CF39: 437 | CG39: 623 | CH39: 207 | CI39: 290 | CJ39: 60 | CM39: 953 | CN39: 410 | CO39: 180 | CP39: 327 | CQ39: 333 | CR39: 680 | CS39: 200 | CT39: 50 | CU39: 160 | CV39: 330 | CW39: 200 | CX39: 390 | CY39: 200 | DA39: 200 | DB39: 60 | DC39: 300 | DD39: 430 | DF39: 339 | DG39: =IFERROR(VLOOKUP(G39,Hoja2!$C$1:$E$1548,3,FALSE),0) -> 7 | DH39: =IFERROR(VLOOKUP(G39,Hoja2!$O$1:$P$1906,2,FALSE),0) -> 0
B40: VSF | D40: MANN-FILTER | E40: PC | F40: Oil Filter | G40: HU 719/6 X | H40: VW Vento 2006 2,5 - Passat 2005 2.0 FSI BLR,BLY,BVX,BVY,BVZ - Audi A3 (Sport Back) 2004 2.0 FSI AXW,BLR/X/Y/MB/VY/VZ | I40: 12 | J40: 738 | K40: 330 | L40: 570 | M40: 796 | N40: 396 | O40: 222 | P40: 710 | Q40: 366 | R40: 318 | S40: 348 | T40: 330 | U40: 228 | V40: 846 | W40: 154 | X40: 350 | Y40: 1350 | Z40: 554 | AA40: 696 | AB40: 80 | AC40: 731 | AD40: 1032 | AE40: 114 | AF40: 456 | AG40: 255 | AH40: 499 | AI40: 1105 | AJ40: 247 | AK40: 1034 | AL40: 461 | AM40: 548 | AN40: 521 | AO40: 358 | AP40: 734 | AQ40: 454 | AR40: 539 | AS40: 454 | AT40: 753 | AU40: 370 | AV40: 267 | AW40: 344 | AX40: 145 | AY40: 641 | AZ40: 521 | BA40: 291 | BB40: 648 | BC40: 290 | BD40: 764 | BE40: 300 | BF40: 524 | BG40: 850 | BH40: 310 | BI40: 291 | BJ40: 591 | BK40: 239 | BM40: 520 | BP40: 250 | BQ40: 660 | BR40: 1030 | BS40: 490 | BT40: 1159 | BU40: 720 | BV40: 31 | BW40: 80 | BX40: 311 | BY40: 579 | BZ40: 539 | CA40: 902 | CB40: 368 | CC40: 31 | CD40: 940 | CE40: 200 | CF40: 530 | CG40: 220 | CH40: 603 | CI40: 1192 | CJ40: 295 | CK40: 10 | CM40: 910 | CO40: 280 | CP40: 440 | CQ40: 504 | CR40: 408 | CS40: 700 | CT40: 588 | CU40: 408 | CV40: 155 | CX40: 1005 | CY40: 442 | CZ40: 110 | DA40: 320 | DB40: 350 | DC40: 330 | DD40: 500 | DE40: 633 | DF40: 300 | DG40: =IFERROR(VLOOKUP(G40,Hoja2!$C$1:$E$1548,3,FALSE),0) -> 300 | DH40: =IFERROR(VLOOKUP(G40,Hoja2!$O$1:$P$1906,2,FALSE),0) -> 615
...

Sheet Hoja2
A1: Category | B1: Subcategory | C1: SKU | D1: Description | E1: 45809 | I1: Family | J1: Region | K1: Salesman | L1: Client | M1: Category | N1: Subcategory | O1: SKU | P1: 45839
A2: PC | B2: Air Filter | C2: C 16 012 | D2: CHEVROLET Cruze 1.4 T 86CID 153CV (Reemplaza a C 14 013) | E2: 542 | H2: C 16 012 | J2: VSF | L2: MANN-FILTER | M2: PC | N2: Air Filter | O2: C 16 012 | P2: 726
A3: PC | B3: Air Filter | C3: C 16 134/2 | D3: Ford Focus 2.0L motor Duratec HE; 1.6L 16V motor Sigma 2008 a†’; 1.8 TDCi motor KKDA 2008 a†’ (Reemplaza a C 16 134/1) | E3: 147 | J3: VSF | L3: MANN-FILTER | M3: PC | N3: Air Filter | O3: C 16 134/2 | P3: 2158
A4: PC | B4: Air Filter | C4: C 18 004 | D4: HONDA CITY 1.5 16V SOHC i-VTEC 07/09 - FIT 1.4 16v 01/09 | E4: 500 | J4: VSF | L4: MANN-FILTER | M4: PC | N4: Air Filter | O4: C 18 004 | P4: 1020
A5: PC | B5: Air Filter | C5: C 2324 | D5: GM AVEO 1,6 L 16V DOHC 2009a†’ SUZUKI S | E5: 140 | J5: VSF | L5: MANN-FILTER | M5: PC | N5: Air Filter | O5: C 2324 | P5: 10
A6: PC | B6: Air Filter | C6: C 24 005 | D6: TOYOTA COROLLA, 1,8 L 16V 2009a†’ | E6: 1000 | J6: VSF | L6: MANN-FILTER | M6: PC | N6: Air Filter | O6: C 24 005 | P6: 1006
A7: PC | B7: Air Filter | C7: C 27 009 | D7: AUDI A3 TFSI 1.4 122 CV y VW TFSI 1.4 Golf 2014a†’ | E7: 451 | J7: VSF | L7: MANN-FILTER | M7: PC | N7: Air Filter | O7: C 27 009 | P7: 720
A8: PC | B8: Air Filter | C8: C 27 063 | D8: TOYOTA Corolla 2.0 170 cv, 2020a†’; Camry, RAV4 2.5 Hib. 218 cv, 2019a†’ | E8: 290 | J8: VSF | L8: MANN-FILTER | M8: PC | N8: Air Filter | O8: C 27 063 | P8: 375
A9: PC | B9: Air Filter | C9: C 36 003 | D9: Citroen DS4 1.6 16V THP 163 cv motor: EP6CDT M; Citroen DS3 1.6 16V Turbo motor EP6DT; Peugeot RCZ 1.6 16V motor EP6CDTX; 3008 1.6 THP; 308 1.6L THP CC y 1.6 GTI; 408 1.6N THP (Sport) motor EP6CDT | E9: 102 | J9: VSF | L9: MANN-FILTER | M9: PC | N9: Air Filter | O9: C 36 003 | P9: 378
A10: CV | B10: Air Filter | C10: CF 1650 | D10: cart. De seg. Para C 26 1100 | E10: 340 | J10: VSF | L10: MANN-FILTER | M10: CV | N10: Air Filter | O10: C 811 | P10: 1630
A11: OHI | B11: Air Filter | C11: CF 810 | D11: (Cart. Segur. para C 30 810/3) | E11: 50 | J11: VSF | L11: MANN-FILTER | M11: CV | N11: Air Filter | O11: CF 1650 | P11: 284
A12: Pick up | B12: Cabin Filter | C12: CU 1919 | D12: TOYOTA: Corolla/Fielder 1.8 16V Flex 2009a†’; Hilux 2.5/3.0 L 16V Diesel 2001a†’; Hilux 2.5/3.0 L 16V Diesel 2005a†’; RAV4 2.0 16V Gas. 2006a†’; Camry 2006a†’; Lexus 2006a†’ | E12: 2231 | J12: VSF | L12: MANN-FILTER | M12: OHI | N12: Air Filter | O12: CF 810 | P12: 54
A13: PC | B13: Cabin Filter | C13: CU 21 000-2 | D13: CitroA«n Peugeot 1,6 16 V Turbo | E13: 838 | J13: VSF | L13: MANN-FILTER | M13: Pick up | N13: Cabin Filter | O13: CU 1919 | P13: 670
A14: PC | B14: Cabin Filter | C14: CU 2141 | D14: CITROEN C4 aircross 2013 / Peugeot 4008 / Mitsubishi Outlander III 2.0 | E14: 300 | J14: VSF | L14: MANN-FILTER | M14: PC | N14: Cabin Filter | O14: CU 21 000-2 | P14: 565
... A98: CV | B98: Oil Filter | C98: WP 11 102/3 | D98: Caterpillar, New Holland, Renault Trucks Varios, Volvo, Bomag | E98: 224 | J98: VSF | L98: MANN-FILTER | M98: CV | N98: Oil Filter | O98: WP 11 102/3 | P98: 65
A99: CV | B99: Coolant Filter | C99: 24112 | D99: Cummins ISX Engine | E99: 12 | J99: MTO | L99: WIX | M99: OHI | N99: Coolant Filter | O99: 24114 | P99: 8
A100: OHI | B100: Fuel Filter | C100: 33122 | D100: Detroit Diesel 8.2 Liter Eng. (81-92) Secondary (10 Micron) | E100: 10 | J100: MTO | L100: WIX | M100: CV | N100: Coolant Filter | O100: 24370 | P100: 24
A101: OHI | B101: Fuel Filter | C101: 33423 | D101: CASE-IH Serie STX / CUMMINS QSX15 / JOHN DEERE Cosechadora 7800 | E101: 6 | J101: MTO | L101: WIX | M101: PC | N101: Fuel Filter | O101: 33031 | P101: 24
A102: OHI | B102: Fuel Filter | C102: 33544 | D102: Thermo King (Secondary...used w/33543 or 33545) (2.460 X 2.830 X 4.620) 3 Holes on Base. | E102: 12 | J102: MTO | L102: WIX | M102: CV | N102: Fuel Filter | O102: 33218 | P102: 16
A103: PC | B103: Fuel Filter | C103: 33565 | D103: HONDA Accord 2.0, 2.0i, 2.0i 16V, 2.2i 16V, 2.2Si VTEC; Civic 1.6 16V - TOYOTA Corolla ELI 1.6i, GLI 1.6i | E103: 6 | J103: MTO | L103: WIX | M103: CV | N103: Fuel Filter | O103: 33231 | P103: 84
A104: OHI | B104: Fuel Filter | C104: 33978 | D104: Excavadoras JOHN DEERE 120D/ 130G/ 160D/ LC 200C/ LC 210LJ | E104: 1 | J104: MTO | L104: WIX | M104: OHI | N104: Fuel Filter | O104: 33394 | P104: 3
A105: OHI | B105: Air Filter | C105: 42217 | D105: Case, Cat, Champion, Kawasaki, Kobelco, JCB, Volvo Secundario del 42216 | E105: 4 | J105: MTO | L105: WIX | M105: OHI | N105: Fuel Filter | O105: 33443 | P105: 6
A106: OHI | B106: Air Filter | C106: 42233 | D106: Caterpillar | E106: 10 | J106: MTO | L106: WIX | M106: OHI | N106: Fuel Filter | O106: 33528 | P106: 1
A107: OHI | B107: Air Filter | C107: 42238 | D107: Komatsu Carretones Autopropulsados de volteo; Compresores | E107: 14 | J107: MTO | L107: WIX | M107: OHI | N107: Fuel Filter | O107: 33609 | P107: 6
A108: OHI | B108: Air Filter | C108: 42359 | D108: Compresores LINCOLN / Equipos BRIGGS AND STRATTON | E108: 4 | J108: MTO | L108: WIX | M108: OHI | N108: Fuel Filter | O108: 33778 | P108: 4
A109: OHI | B109: Air Filter | C109: 46595 | D109: cart. De seg. De 46607 | E109: 6 | J109: MTO | L109: WIX | M109: OHI | N109: Fuel Filter | O109: 33785 | P109: 6
A110: OHI | B110: Air Filter | C110: 46734 | D110: IHC/Dresser Graders, Komatsu (Outer used w/46711) | E110: 2 | J110: MTO | L110: WIX | M110: OHI | N110: Air Filter | O110: 42047 | P110: 3
... A131: CV | B131: Oil Filter | C131: 57791 | D131: Renault Magnum AE 420, Manager G 300, Premium HR 385.24T/19T-340.19T. | E131: 6 | J131: MTO | L131: WIX | M131: OHI | N131: Air Filter | O131: 46830 | P131: 2
A132: OHI | B132: Fuel Filter | C132: 33651XE | D132: High efficiency version of 33651 (5 micron) | E132: 6 | J132: MTO | L132: WIX | M132: PC | N132: Air Filter | O132: 49058 | P132: 15
A133: OHI | B133: Oil Filter | C133: 51006E | D133: Mercedes-Benz, Still | E133: 4 | J133: MTO | L133: WIX | M133: PC | N133: Air Filter | O133: 49065 | P133: 18
A134: CV | B134: Oil Filter | C134: 51063E | D134: Mercedes-Benz c/mot. OM 366, 366 A/LA, 366 A Turbo (Reemplaza a WL51142) | E134: 12 | J134: MTO | L134: WIX | M134: PC | N134: Air Filter | O134: 49070 | P134: 12
A135: PC | B135: Oil Filter | C135: 51085XP | D135: Version long life de 51085 o WL7067 con medio filtrante sintetico | E135: 6 | J135: MTO | L135: WIX | M135: OHI | N135: Cabin Filter | O135: 49161 | P135: 6
A136: PC | B136: Oil Filter | C136: 51093E | D136: Toyota Coaster STD (97a†’), Land Cruiser 4.2 (96a†’), SW4 3.0 TD | E136: 8 | J136: MTO | L136: WIX | M136: OHI | N136: Air Filter | O136: 49183 | P136: 268
A137: CV | B137: Oil Filter | C137: 51099E | D137: Perkins (equiv.32599); Ford c/mot. Perkins (a†’77); BMW (a†’80) | E137: 13 | J137: MTO | L137: WIX | M137: OHI | N137: Air Filter | O137: 49396 | P137: 2
A138: PC | B138: Oil Filter | C138: 51515R | D138: LANZAMIENTO | E138: 102 | J138: MTO | L138: WIX | M138: OHI | N138: Air Filter | O138: 49441 | P138: 1
A139: OHI | B139: AOS | C139: 63 400 51 141 | D139: Filtro EDM - Equipos de ElectroerosiA³n | E139: 10 | J139: MTO | L139: WIX | M139: Pick up | N139: Air Filter | O139: 49463 | P139: 6
A140: CV | B140: Oil Filter | C140: 92041E | D140: MERCEDES BENZ Actros 2041, 1938 LS, 2638 LS (Reemplaza a WL57657) | E140: 18 | J140: MTO | L140: WIX | M140: OHI | N140: Air Filter | O140: 49599 | P140: 2
A141: CV | B141: Air Filter | C141: 93220E | D141: Nissan Modelo ECO - T100/54 3.0 Turbodiesel Intercooler (Reemplaza a WA46818) | E141: 6 | J141: MTO | L141: WIX | M141: OHI | N141: Air Filter | O141: 49669 | P141: 2
A142: CV | B142: Air Filter | C142: 93911E | D142: Camiones SCANIA 2013a†’ DC13 (G,P,R) (elemento secundario de WA10856) | E142: 6 | J142: MTO | L142: WIX | M142: OHI | N142: Air Filter | O142: 49708 | P142: 12
